<?xml version="1.0"?>
<robot name="robot_arm" xmlns:xacro="http://www.ros.org/wiki/xacro">

    <xacro:include filename="$(find robot_arm_description)/urdf/materials.xacro" />
    <xacro:include filename="$(find robot_arm_description)/urdf/ros2_control.xacro" />
    <xacro:include filename="$(find robot_arm_description)/urdf/robot_arm.gazebo" />

    <link name="base_link">
        <inertial>
            <origin xyz="-0.00010789040737851121 -2.387011716501852e-05 0.003254077562984443"
                rpy="0 0 0" />
            <mass value="0.0923352856253466" />
            <inertia ixx="0.000295" iyy="0.000295" izz="0.00059" ixy="0.0" iyz="-0.0" ixz="-0.0" />
        </inertial>
        <visual>
            <origin xyz="0 0 0" rpy="0 0 0" />
            <geometry>
                <mesh filename="file://$(find robot_arm_description)/meshes/base_link.stl"
                    scale="0.001 0.001 0.001" />
            </geometry>
            <material name="silver" />
        </visual>
        <collision>
            <origin xyz="0 0 0" rpy="0 0 0" />
            <geometry>
                <mesh filename="file://$(find robot_arm_description)/meshes/base_link.stl"
                    scale="0.001 0.001 0.001" />
            </geometry>
        </collision>
    </link>

    <link name="Base_bottom_1">
        <inertial>
            <origin xyz="-0.0007287594569246752 -0.00023276962486802833 0.007529319876131384"
                rpy="0 0 0" />
            <mass value="0.31316469015599396" />
            <inertia ixx="0.000464" iyy="0.000452" izz="0.000905" ixy="5e-06" iyz="0.0" ixz="1e-06" />
        </inertial>
        <visual>
            <origin xyz="0.000112 2.5e-05 -0.010138" rpy="0 0 0" />
            <geometry>
                <mesh filename="file://$(find robot_arm_description)/meshes/Base_bottom_1.stl"
                    scale="0.001 0.001 0.001" />
            </geometry>
            <material name="silver" />
        </visual>
        <collision>
            <origin xyz="0.000112 2.5e-05 -0.010138" rpy="0 0 0" />
            <geometry>
                <mesh filename="file://$(find robot_arm_description)/meshes/Base_bottom_1.stl"
                    scale="0.001 0.001 0.001" />
            </geometry>
        </collision>
    </link>

    <link name="Base_cylinder_1">
        <inertial>
            <origin xyz="-1.3465766603011899e-05 -3.016098464437629e-06 0.02093321099830847"
                rpy="0 0 0" />
            <mass value="0.1877283625038977" />
            <inertia ixx="0.0005" iyy="0.0005" izz="0.000941" ixy="0.0" iyz="-0.0" ixz="-0.0" />
        </inertial>
        <visual>
            <origin xyz="0.000122 2.8e-05 -0.025138" rpy="0 0 0" />
            <geometry>
                <mesh filename="file://$(find robot_arm_description)/meshes/Base_cylinder_1.stl"
                    scale="0.001 0.001 0.001" />
            </geometry>
            <material name="silver" />
        </visual>
        <collision>
            <origin xyz="0.000122 2.8e-05 -0.025138" rpy="0 0 0" />
            <geometry>
                <mesh filename="file://$(find robot_arm_description)/meshes/Base_cylinder_1.stl"
                    scale="0.001 0.001 0.001" />
            </geometry>
        </collision>
    </link>

    <link name="Base_top_1">
        <inertial>
            <origin xyz="-0.000745633070446639 2.3596155231202955e-06 0.004806450018607744"
                rpy="0 0 0" />
            <mass value="0.2042179409587294" />
            <inertia ixx="0.000325" iyy="0.000303" izz="0.000625" ixy="-0.0" iyz="-0.0" ixz="-0.0" />
        </inertial>
        <visual>
            <origin xyz="0.000148 3.4e-05 -0.065138" rpy="0 0 0" />
            <geometry>
                <mesh filename="file://$(find robot_arm_description)/meshes/Base_top_1.stl"
                    scale="0.001 0.001 0.001" />
            </geometry>
            <material name="silver" />
        </visual>
        <collision>
            <origin xyz="0.000148 3.4e-05 -0.065138" rpy="0 0 0" />
            <geometry>
                <mesh filename="file://$(find robot_arm_description)/meshes/Base_top_1.stl"
                    scale="0.001 0.001 0.001" />
            </geometry>
        </collision>
    </link>

    <link name="Bearing_clamp_1">
        <inertial>
            <origin xyz="-1.3366676636427993e-06 -1.656328060335217e-07 0.0017876362387215933"
                rpy="0 0 0" />
            <mass value="0.003107973401790518" />
            <inertia ixx="1e-06" iyy="0.0" izz="1e-06" ixy="-0.0" iyz="-0.0" ixz="-0.0" />
        </inertial>
        <visual>
            <origin xyz="0.000154 3.6e-05 -0.075138" rpy="0 0 0" />
            <geometry>
                <mesh filename="file://$(find robot_arm_description)/meshes/Bearing_clamp_1.stl"
                    scale="0.001 0.001 0.001" />
            </geometry>
            <material name="silver" />
        </visual>
        <collision>
            <origin xyz="0.000154 3.6e-05 -0.075138" rpy="0 0 0" />
            <geometry>
                <mesh filename="file://$(find robot_arm_description)/meshes/Bearing_clamp_1.stl"
                    scale="0.001 0.001 0.001" />
            </geometry>
        </collision>
    </link>

    <link name="Bearing_ring_1">
        <inertial>
            <origin xyz="3.3057221366983086e-07 -2.518657375805299e-07 -0.001195674839012159"
                rpy="0 0 0" />
            <mass value="0.02702780685873039" />
            <inertia ixx="6.4e-05" iyy="6.4e-05" izz="0.000128" ixy="0.0" iyz="-0.0" ixz="-0.0" />
        </inertial>
        <visual>
            <origin xyz="0.000156 3.6e-05 -0.078638" rpy="0 0 0" />
            <geometry>
                <mesh filename="file://$(find robot_arm_description)/meshes/Bearing_ring_1.stl"
                    scale="0.001 0.001 0.001" />
            </geometry>
            <material name="silver" />
        </visual>
        <collision>
            <origin xyz="0.000156 3.6e-05 -0.078638" rpy="0 0 0" />
            <geometry>
                <mesh filename="file://$(find robot_arm_description)/meshes/Bearing_ring_1.stl"
                    scale="0.001 0.001 0.001" />
            </geometry>
        </collision>
    </link>

    <link name="Gear_12T_1">
        <inertial>
            <origin xyz="4.8998330119377764e-05 -0.009000418156728248 0.0016602830082886877"
                rpy="0 0 0" />
            <mass value="0.0016560412373827706" />
            <inertia ixx="0.0" iyy="0.0" izz="0.0" ixy="-0.0" iyz="-0.0" ixz="0.0" />
        </inertial>
        <visual>
            <origin xyz="0.048113 -0.009181 -0.075108" rpy="0 0 0" />
            <geometry>
                <mesh filename="file://$(find robot_arm_description)/meshes/Gear_12T_1.stl"
                    scale="0.001 0.001 0.001" />
            </geometry>
            <material name="silver" />
        </visual>
        <collision>
            <origin xyz="0.048113 -0.009181 -0.075108" rpy="0 0 0" />
            <geometry>
                <mesh filename="file://$(find robot_arm_description)/meshes/Gear_12T_1.stl"
                    scale="0.001 0.001 0.001" />
            </geometry>
        </collision>
    </link>

    <link name="Gear_27T_1">
        <inertial>
            <origin xyz="-0.00010601364303874233 -0.013000877478900216 0.006000702493903193"
                rpy="0 0 0" />
            <mass value="0.008213557037232692" />
            <inertia ixx="0.0" iyy="0.0" izz="1e-06" ixy="-0.0" iyz="-0.0" ixz="-0.0" />
        </inertial>
        <visual>
            <origin xyz="-0.040402 -0.012281 -0.075166" rpy="0 0 0" />
            <geometry>
                <mesh filename="file://$(find robot_arm_description)/meshes/Gear_27T_1.stl"
                    scale="0.001 0.001 0.001" />
            </geometry>
            <material name="silver" />
        </visual>
        <collision>
            <origin xyz="-0.040402 -0.012281 -0.075166" rpy="0 0 0" />
            <geometry>
                <mesh filename="file://$(find robot_arm_description)/meshes/Gear_27T_1.stl"
                    scale="0.001 0.001 0.001" />
            </geometry>
        </collision>
    </link>

    <link name="Potentiometer_1">
        <inertial>
            <origin xyz="1.1743567394917331e-05 3.2676931635859045e-06 -0.018955332442223957"
                rpy="0 0 0" />
            <mass value="0.010035763547273252" />
            <inertia ixx="1e-06" iyy="1e-06" izz="1e-06" ixy="-0.0" iyz="0.0" ixz="0.0" />
        </inertial>
        <visual>
            <origin xyz="0.04815 -0.000182 -0.070107" rpy="0 0 0" />
            <geometry>
                <mesh filename="file://$(find robot_arm_description)/meshes/Potentiometer_1.stl"
                    scale="0.001 0.001 0.001" />
            </geometry>
            <material name="silver" />
        </visual>
        <collision>
            <origin xyz="0.04815 -0.000182 -0.070107" rpy="0 0 0" />
            <geometry>
                <mesh filename="file://$(find robot_arm_description)/meshes/Potentiometer_1.stl"
                    scale="0.001 0.001 0.001" />
            </geometry>
        </collision>
    </link>

    <link name="Steel_ball_10mm_1">
        <inertial>
            <origin xyz="1.0122989557714845e-07 -4.422076359603122e-07 -1.9021058737800356e-07"
                rpy="0 0 0" />
            <mass value="0.0041887902047863905" />
            <inertia ixx="0.0" iyy="0.0" izz="0.0" ixy="-0.0" iyz="0.0" ixz="0.0" />
        </inertial>
        <visual>
            <origin xyz="-0.055442 -0.039976 -0.079735" rpy="0 0 0" />
            <geometry>
                <mesh filename="file://$(find robot_arm_description)/meshes/Steel_ball_10mm_1.stl"
                    scale="0.001 0.001 0.001" />
            </geometry>
            <material name="silver" />
        </visual>
        <collision>
            <origin xyz="-0.055442 -0.039976 -0.079735" rpy="0 0 0" />
            <geometry>
                <sphere radius="0.005" />
            </geometry>
        </collision>
    </link>

    <link name="Steel_ball_10mm_4">
        <inertial>
            <origin xyz="2.381829425704418e-08 3.206416161888326e-07 3.5668395181875923e-09"
                rpy="0 0 0" />
            <mass value="0.0041887902047863905" />
            <inertia ixx="0.0" iyy="0.0" izz="0.0" ixy="0.0" iyz="-0.0" ixz="-0.0" />
        </inertial>
        <visual>
            <origin xyz="-0.021305 -0.065014 -0.079717" rpy="0 0 0" />
            <geometry>
                <mesh filename="file://$(find robot_arm_description)/meshes/Steel_ball_10mm_4.stl"
                    scale="0.001 0.001 0.001" />
            </geometry>
            <material name="silver" />
        </visual>
        <collision>
            <origin xyz="-0.021305 -0.065014 -0.079717" rpy="0 0 0" />
            <geometry>
                <sphere radius="0.005" />
            </geometry>
        </collision>
    </link>

    <link name="Steel_ball_10mm_3">
        <inertial>
            <origin xyz="1.3751947359336159e-07 -1.6765396858298143e-07 -2.2915818026492119e-07"
                rpy="0 0 0" />
            <mass value="0.0041887902047863905" />
            <inertia ixx="0.0" iyy="0.0" izz="0.0" ixy="0.0" iyz="0.0" ixz="-0.0" />
        </inertial>
        <visual>
            <origin xyz="0.02103 -0.065206 -0.07969" rpy="0 0 0" />
            <geometry>
                <mesh filename="file://$(find robot_arm_description)/meshes/Steel_ball_10mm_3.stl"
                    scale="0.001 0.001 0.001" />
            </geometry>
            <material name="silver" />
        </visual>
        <collision>
            <origin xyz="0.02103 -0.065206 -0.07969" rpy="0 0 0" />
            <geometry>
                <sphere radius="0.005" />
            </geometry>
        </collision>
    </link>

    <link name="Steel_ball_10mm_2">
        <inertial>
            <origin xyz="-7.001027908792867e-08 -5.805623353588585e-08 -4.864102955276506e-07"
                rpy="0 0 0" />
            <mass value="0.0041887902047863905" />
            <inertia ixx="0.0" iyy="0.0" izz="0.0" ixy="0.0" iyz="-0.0" ixz="-0.0" />
        </inertial>
        <visual>
            <origin xyz="0.055392 -0.040477 -0.079664" rpy="0 0 0" />
            <geometry>
                <mesh filename="file://$(find robot_arm_description)/meshes/Steel_ball_10mm_2.stl"
                    scale="0.001 0.001 0.001" />
            </geometry>
            <material name="silver" />
        </visual>
        <collision>
            <origin xyz="0.055392 -0.040477 -0.079664" rpy="0 0 0" />
            <geometry>
                <sphere radius="0.005" />
            </geometry>
        </collision>
    </link>

    <link name="Steel_ball_10mm_10">
        <inertial>
            <origin xyz="-4.034230758065416e-07 2.4506441546602543e-07 2.6118835047550526e-07"
                rpy="0 0 0" />
            <mass value="0.0041887902047863905" />
            <inertia ixx="0.0" iyy="0.0" izz="0.0" ixy="-0.0" iyz="0.0" ixz="-0.0" />
        </inertial>
        <visual>
            <origin xyz="0.068656 -0.000273 -0.079648" rpy="0 0 0" />
            <geometry>
                <mesh filename="file://$(find robot_arm_description)/meshes/Steel_ball_10mm_10.stl"
                    scale="0.001 0.001 0.001" />
            </geometry>
            <material name="silver" />
        </visual>
        <collision>
            <origin xyz="0.068656 -0.000273 -0.079648" rpy="0 0 0" />
            <geometry>
                <sphere radius="0.005" />
            </geometry>
        </collision>
    </link>

    <link name="Steel_ball_10mm_9">
        <inertial>
            <origin xyz="1.664596320644085e-07 -4.998295579491312e-07 3.8813772720858175e-07"
                rpy="0 0 0" />
            <mass value="0.0041887902047863905" />
            <inertia ixx="0.0" iyy="0.0" izz="0.0" ixy="0.0" iyz="-0.0" ixz="0.0" />
        </inertial>
        <visual>
            <origin xyz="-0.068342 0.000346 -0.079736" rpy="0 0 0" />
            <geometry>
                <mesh filename="file://$(find robot_arm_description)/meshes/Steel_ball_10mm_9.stl"
                    scale="0.001 0.001 0.001" />
            </geometry>
            <material name="silver" />
        </visual>
        <collision>
            <origin xyz="-0.068342 0.000346 -0.079736" rpy="0 0 0" />
            <geometry>
                <sphere radius="0.005" />
            </geometry>
        </collision>
    </link>

    <link name="Steel_ball_10mm_8">
        <inertial>
            <origin xyz="-1.6695316435583196e-07 -1.9670890899492477e-07 1.3573637323849308e-07"
                rpy="0 0 0" />
            <mass value="0.0041887902047863905" />
            <inertia ixx="0.0" iyy="0.0" izz="0.0" ixy="0.0" iyz="0.0" ixz="0.0" />
        </inertial>
        <visual>
            <origin xyz="-0.055078 0.04055 -0.079721" rpy="0 0 0" />
            <geometry>
                <mesh filename="file://$(find robot_arm_description)/meshes/Steel_ball_10mm_8.stl"
                    scale="0.001 0.001 0.001" />
            </geometry>
            <material name="silver" />
        </visual>
        <collision>
            <origin xyz="-0.055078 0.04055 -0.079721" rpy="0 0 0" />
            <geometry>
                <sphere radius="0.005" />
            </geometry>
        </collision>
    </link>

    <link name="Steel_ball_10mm_5">
        <inertial>
            <origin xyz="-3.7448291683242485e-07 -8.711117421844605e-08 -1.2151574207974747e-07"
                rpy="0 0 0" />
            <mass value="0.0041887902047863905" />
            <inertia ixx="0.0" iyy="0.0" izz="0.0" ixy="0.0" iyz="0.0" ixz="0.0" />
        </inertial>
        <visual>
            <origin xyz="-0.020716 0.065279 -0.079695" rpy="0 0 0" />
            <geometry>
                <mesh filename="file://$(find robot_arm_description)/meshes/Steel_ball_10mm_5.stl"
                    scale="0.001 0.001 0.001" />
            </geometry>
            <material name="silver" />
        </visual>
        <collision>
            <origin xyz="-0.020716 0.065279 -0.079695" rpy="0 0 0" />
            <geometry>
                <sphere radius="0.005" />
            </geometry>
        </collision>
    </link>

    <link name="Steel_ball_10mm_6">
        <inertial>
            <origin xyz="-2.6078173749610745e-07 4.2459324066379533e-07 -3.542407619044896e-07"
                rpy="0 0 0" />
            <mass value="0.0041887902047863905" />
            <inertia ixx="0.0" iyy="0.0" izz="0.0" ixy="0.0" iyz="0.0" ixz="0.0" />
        </inertial>
        <visual>
            <origin xyz="0.021619 0.065088 -0.079668" rpy="0 0 0" />
            <geometry>
                <mesh filename="file://$(find robot_arm_description)/meshes/Steel_ball_10mm_6.stl"
                    scale="0.001 0.001 0.001" />
            </geometry>
            <material name="silver" />
        </visual>
        <collision>
            <origin xyz="0.021619 0.065088 -0.079668" rpy="0 0 0" />
            <geometry>
                <sphere radius="0.005" />
            </geometry>
        </collision>
    </link>

    <link name="Steel_ball_10mm_7">
        <inertial>
            <origin xyz="-3.381933390209091e-07 1.8744249257601764e-07 -1.6046333489727616e-07"
                rpy="0 0 0" />
            <mass value="0.0041887902047863905" />
            <inertia ixx="0.0" iyy="0.0" izz="0.0" ixy="0.0" iyz="-0.0" ixz="0.0" />
        </inertial>
        <visual>
            <origin xyz="0.055756 0.040049 -0.07965" rpy="0 0 0" />
            <geometry>
                <mesh filename="file://$(find robot_arm_description)/meshes/Steel_ball_10mm_7.stl"
                    scale="0.001 0.001 0.001" />
            </geometry>
            <material name="silver" />
        </visual>
        <collision>
            <origin xyz="0.055756 0.040049 -0.07965" rpy="0 0 0" />
            <geometry>
                <sphere radius="0.005" />
            </geometry>
        </collision>
    </link>

    <link name="Bearing_clamp_2">
        <inertial>
            <origin xyz="-1.4751095382383247e-06 -3.1737161876507476e-07 0.0017876506239141061"
                rpy="0 0 0" />
            <mass value="0.003107973401790518" />
            <inertia ixx="1e-06" iyy="0.0" izz="1e-06" ixy="-0.0" iyz="-0.0" ixz="-0.0" />
        </inertial>
        <visual>
            <origin xyz="0.000112 2.5e-05 -0.010138" rpy="0 0 0" />
            <geometry>
                <mesh filename="file://$(find robot_arm_description)/meshes/Bearing_clamp_2.stl"
                    scale="0.001 0.001 0.001" />
            </geometry>
            <material name="silver" />
        </visual>
        <collision>
            <origin xyz="0.000112 2.5e-05 -0.010138" rpy="0 0 0" />
            <geometry>
                <mesh filename="file://$(find robot_arm_description)/meshes/Bearing_clamp_2.stl"
                    scale="0.001 0.001 0.001" />
            </geometry>
        </collision>
    </link>

    <link name="Rotating_plate_1">
        <inertial>
            <origin xyz="-9.26990489874099e-06 -0.0001520530105522425 0.012543244766787184"
                rpy="0 0 0" />
            <mass value="0.32804852666215706" />
            <inertia ixx="0.000591" iyy="0.000585" izz="0.001118" ixy="-0.0" iyz="-0.0" ixz="-0.0" />
        </inertial>
        <visual>
            <origin xyz="0.000157 3.7e-05 -0.079692" rpy="0 0 0" />
            <geometry>
                <mesh filename="file://$(find robot_arm_description)/meshes/Rotating_plate_1.stl"
                    scale="0.001 0.001 0.001" />
            </geometry>
            <material name="silver" />
        </visual>
        <collision>
            <origin xyz="0.000157 3.7e-05 -0.079692" rpy="0 0 0" />
            <geometry>
                <mesh filename="file://$(find robot_arm_description)/meshes/Rotating_plate_1.stl"
                    scale="0.001 0.001 0.001" />
            </geometry>
        </collision>
    </link>

    <link name="Rotating_plate_clamp_1">
        <inertial>
            <origin xyz="8.546854088575616e-07 7.680939084973217e-07 -0.0017784341539336425"
                rpy="0 0 0" />
            <mass value="0.0010291248849583485" />
            <inertia ixx="0.0" iyy="0.0" izz="0.0" ixy="0.0" iyz="-0.0" ixz="-0.0" />
        </inertial>
        <visual>
            <origin xyz="0.000114 2.6e-05 -0.013192" rpy="0 0 0" />
            <geometry>
                <mesh
                    filename="file://$(find robot_arm_description)/meshes/Rotating_plate_clamp_1.stl"
                    scale="0.001 0.001 0.001" />
            </geometry>
            <material name="silver" />
        </visual>
        <collision>
            <origin xyz="0.000114 2.6e-05 -0.013192" rpy="0 0 0" />
            <geometry>
                <mesh
                    filename="file://$(find robot_arm_description)/meshes/Rotating_plate_clamp_1.stl"
                    scale="0.001 0.001 0.001" />
            </geometry>
        </collision>
    </link>

    <link name="Base_servo_mount_1">
        <inertial>
            <origin xyz="-0.00013783279446091118 0.013368633325555225 0.0424548056670454"
                rpy="0 0 0" />
            <mass value="0.05643617063632359" />
            <inertia ixx="4.7e-05" iyy="2.5e-05" izz="2.4e-05" ixy="-0.0" iyz="0.0" ixz="-0.0" />
        </inertial>
        <visual>
            <origin xyz="0.039568 0.013384 -0.102165" rpy="0 0 0" />
            <geometry>
                <mesh filename="file://$(find robot_arm_description)/meshes/Base_servo_mount_1.stl"
                    scale="0.001 0.001 0.001" />
            </geometry>
            <material name="silver" />
        </visual>
        <collision>
            <origin xyz="0.039568 0.013384 -0.102165" rpy="0 0 0" />
            <geometry>
                <mesh filename="file://$(find robot_arm_description)/meshes/Base_servo_mount_1.stl"
                    scale="0.001 0.001 0.001" />
            </geometry>
        </collision>
    </link>

    <link name="Base_servo_mount__1__1">
        <inertial>
            <origin xyz="0.07278432508951847 -0.0005201241386764844 -0.0005004526552928601"
                rpy="0 0 0" />
            <mass value="0.05643617063632359" />
            <inertia ixx="4.7e-05" iyy="2.5e-05" izz="2.4e-05" ixy="-0.0" iyz="-0.0" ixz="0.0" />
        </inertial>
        <visual>
            <origin xyz="0.032 7e-05 -0.145172" rpy="0 0 0" />
            <geometry>
                <mesh
                    filename="file://$(find robot_arm_description)/meshes/Base_servo_mount__1__1.stl"
                    scale="0.001 0.001 0.001" />
            </geometry>
            <material name="silver" />
        </visual>
        <collision>
            <origin xyz="0.032 7e-05 -0.145172" rpy="0 0 0" />
            <geometry>
                <mesh
                    filename="file://$(find robot_arm_description)/meshes/Base_servo_mount__1__1.stl"
                    scale="0.001 0.001 0.001" />
            </geometry>
        </collision>
    </link>

    <link name="Lower_arm_left_1">
        <inertial>
            <origin xyz="0.004968142806479989 0.09640631018726398 1.911574026738916e-05" rpy="0 0 0" />
            <mass value="0.2987339896749546" />
            <inertia ixx="0.001237" iyy="0.000105" izz="0.001149" ixy="1.8e-05" iyz="-0.0" ixz="0.0" />
        </inertial>
        <visual>
            <origin xyz="0.032 7e-05 -0.145172" rpy="0 0 0" />
            <geometry>
                <mesh filename="file://$(find robot_arm_description)/meshes/Lower_arm_left_1.stl"
                    scale="0.001 0.001 0.001" />
            </geometry>
            <material name="silver" />
        </visual>
        <collision>
            <origin xyz="0.032 7e-05 -0.145172" rpy="0 0 0" />
            <geometry>
                <mesh filename="file://$(find robot_arm_description)/meshes/Lower_arm_left_1.stl"
                    scale="0.001 0.001 0.001" />
            </geometry>
        </collision>
    </link>

    <link name="Lower_arm_right_1">
        <inertial>
            <origin xyz="0.04648653968256619 0.09006556081212144 4.45009070199065e-05" rpy="0 0 0" />
            <mass value="0.2781324221892311" />
            <inertia ixx="0.001108" iyy="0.000104" izz="0.001022" ixy="-3.1e-05" iyz="-0.0"
                ixz="0.0" />
        </inertial>
        <visual>
            <origin xyz="0.018597 -0.000369 -0.145181" rpy="0 0 0" />
            <geometry>
                <mesh filename="file://$(find robot_arm_description)/meshes/Lower_arm_right_1.stl"
                    scale="0.001 0.001 0.001" />
            </geometry>
            <material name="silver" />
        </visual>
        <collision>
            <origin xyz="0.018597 -0.000369 -0.145181" rpy="0 0 0" />
            <geometry>
                <mesh filename="file://$(find robot_arm_description)/meshes/Lower_arm_right_1.stl"
                    scale="0.001 0.001 0.001" />
            </geometry>
        </collision>
    </link>

    <link name="Lower_arm_bushing__1__1">
        <inertial>
            <origin xyz="0.019399558012763107 -0.00013880255154705146 1.2580737335121661e-05"
                rpy="0 0 0" />
            <mass value="0.004315068026843927" />
            <inertia ixx="0.0" iyy="1e-06" izz="1e-06" ixy="0.0" iyz="0.0" ixz="-0.0" />
        </inertial>
        <visual>
            <origin xyz="0.01774 -0.120366 -0.145201" rpy="0 0 0" />
            <geometry>
                <mesh
                    filename="file://$(find robot_arm_description)/meshes/Lower_arm_bushing__1__1.stl"
                    scale="0.001 0.001 0.001" />
            </geometry>
            <material name="silver" />
        </visual>
        <collision>
            <origin xyz="0.01774 -0.120366 -0.145201" rpy="0 0 0" />
            <geometry>
                <mesh
                    filename="file://$(find robot_arm_description)/meshes/Lower_arm_bushing__1__1.stl"
                    scale="0.001 0.001 0.001" />
            </geometry>
        </collision>
    </link>

    <link name="Lower_arm_bushing_1">
        <inertial>
            <origin xyz="0.01939983464147311 -0.00013839961902882558 1.2148748198659298e-05"
                rpy="0 0 0" />
            <mass value="0.004315068026843927" />
            <inertia ixx="0.0" iyy="1e-06" izz="1e-06" ixy="0.0" iyz="0.0" ixz="-0.0" />
        </inertial>
        <visual>
            <origin xyz="0.018133 -0.065367 -0.145192" rpy="0 0 0" />
            <geometry>
                <mesh filename="file://$(find robot_arm_description)/meshes/Lower_arm_bushing_1.stl"
                    scale="0.001 0.001 0.001" />
            </geometry>
            <material name="silver" />
        </visual>
        <collision>
            <origin xyz="0.018133 -0.065367 -0.145192" rpy="0 0 0" />
            <geometry>
                <mesh filename="file://$(find robot_arm_description)/meshes/Lower_arm_bushing_1.stl"
                    scale="0.001 0.001 0.001" />
            </geometry>
        </collision>
    </link>

    <link name="Center_arm_1">
        <inertial>
            <origin xyz="0.017844375764309618 -0.0008444366165445694 0.0578139285641546" rpy="0 0 0" />
            <mass value="0.2964599813425893" />
            <inertia ixx="0.000725" iyy="0.000678" izz="9.1e-05" ixy="-0.0" iyz="6e-06" ixz="0.0" />
        </inertial>
        <visual>
            <origin xyz="0.017276 -0.185364 -0.145212" rpy="0 0 0" />
            <geometry>
                <mesh filename="file://$(find robot_arm_description)/meshes/Center_arm_1.stl"
                    scale="0.001 0.001 0.001" />
            </geometry>
            <material name="silver" />
        </visual>
        <collision>
            <origin xyz="0.017276 -0.185364 -0.145212" rpy="0 0 0" />
            <geometry>
                <mesh filename="file://$(find robot_arm_description)/meshes/Center_arm_1.stl"
                    scale="0.001 0.001 0.001" />
            </geometry>
        </collision>
    </link>

    <link name="Center_arm_bearing_guide__1__1">
        <inertial>
            <origin xyz="0.0032220866840599466 -2.2873845896054235e-05 2.3268126632391972e-06"
                rpy="0 0 0" />
            <mass value="0.003958021366840176" />
            <inertia ixx="0.0" iyy="0.0" izz="0.0" ixy="-0.0" iyz="-0.0" ixz="0.0" />
        </inertial>
        <visual>
            <origin xyz="-0.010723 -0.185164 -0.14523" rpy="0 0 0" />
            <geometry>
                <mesh
                    filename="file://$(find robot_arm_description)/meshes/Center_arm_bearing_guide__1__1.stl"
                    scale="0.001 0.001 0.001" />
            </geometry>
            <material name="silver" />
        </visual>
        <collision>
            <origin xyz="-0.010723 -0.185164 -0.14523" rpy="0 0 0" />
            <geometry>
                <mesh
                    filename="file://$(find robot_arm_description)/meshes/Center_arm_bearing_guide__1__1.stl"
                    scale="0.001 0.001 0.001" />
            </geometry>
        </collision>
    </link>

    <link name="Bearing_holder_1">
        <inertial>
            <origin xyz="0.003920791928682797 -2.7548714614911152e-05 2.389916507000711e-06"
                rpy="0 0 0" />
            <mass value="0.0054576424055458195" />
            <inertia ixx="1e-06" iyy="0.0" izz="1e-06" ixy="-0.0" iyz="-0.0" ixz="0.0" />
        </inertial>
        <visual>
            <origin xyz="-0.024123 -0.185068 -0.145239" rpy="0 0 0" />
            <geometry>
                <mesh filename="file://$(find robot_arm_description)/meshes/Bearing_holder_1.stl"
                    scale="0.001 0.001 0.001" />
            </geometry>
            <material name="silver" />
        </visual>
        <collision>
            <origin xyz="-0.024123 -0.185068 -0.145239" rpy="0 0 0" />
            <geometry>
                <mesh filename="file://$(find robot_arm_description)/meshes/Bearing_holder_1.stl"
                    scale="0.001 0.001 0.001" />
            </geometry>
        </collision>
    </link>

    <link name="Center_arm_bearing_guide_1">
        <inertial>
            <origin xyz="0.003221413867448626 -2.3484164195980428e-05 2.300808664534859e-06"
                rpy="0 0 0" />
            <mass value="0.003958021366840176" />
            <inertia ixx="0.0" iyy="0.0" izz="0.0" ixy="-0.0" iyz="-0.0" ixz="0.0" />
        </inertial>
        <visual>
            <origin xyz="-0.010648 -0.185145 -0.26273" rpy="0 0 0" />
            <geometry>
                <mesh
                    filename="file://$(find robot_arm_description)/meshes/Center_arm_bearing_guide_1.stl"
                    scale="0.001 0.001 0.001" />
            </geometry>
            <material name="silver" />
        </visual>
        <collision>
            <origin xyz="-0.010648 -0.185145 -0.26273" rpy="0 0 0" />
            <geometry>
                <mesh
                    filename="file://$(find robot_arm_description)/meshes/Center_arm_bearing_guide_1.stl"
                    scale="0.001 0.001 0.001" />
            </geometry>
        </collision>
    </link>

    <link name="Bearing_holder__1__1">
        <inertial>
            <origin xyz="-0.0035202345828598547 2.4977570274559158e-05 -2.419630403927009e-06"
                rpy="0 0 0" />
            <mass value="0.0054576424055458195" />
            <inertia ixx="1e-06" iyy="0.0" izz="1e-06" ixy="-0.0" iyz="-0.0" ixz="0.0" />
        </inertial>
        <visual>
            <origin xyz="-0.024047 -0.185049 -0.262739" rpy="0 0 0" />
            <geometry>
                <mesh
                    filename="file://$(find robot_arm_description)/meshes/Bearing_holder__1__1.stl"
                    scale="0.001 0.001 0.001" />
            </geometry>
            <material name="silver" />
        </visual>
        <collision>
            <origin xyz="-0.024047 -0.185049 -0.262739" rpy="0 0 0" />
            <geometry>
                <mesh
                    filename="file://$(find robot_arm_description)/meshes/Bearing_holder__1__1.stl"
                    scale="0.001 0.001 0.001" />
            </geometry>
        </collision>
    </link>

    <link name="Center_arm_bearing_guide_clamp__1__1">
        <inertial>
            <origin xyz="-0.00484238366198313 3.5044619743962446e-05 -2.843544512798335e-06"
                rpy="0 0 0" />
            <mass value="0.00032043263318911203" />
            <inertia ixx="0.0" iyy="0.0" izz="0.0" ixy="-0.0" iyz="-0.0" ixz="0.0" />
        </inertial>
        <visual>
            <origin xyz="-0.032523 -0.185008 -0.145244" rpy="0 0 0" />
            <geometry>
                <mesh
                    filename="file://$(find robot_arm_description)/meshes/Center_arm_bearing_guide_clamp__1__1.stl"
                    scale="0.001 0.001 0.001" />
            </geometry>
            <material name="silver" />
        </visual>
        <collision>
            <origin xyz="-0.032523 -0.185008 -0.145244" rpy="0 0 0" />
            <geometry>
                <mesh
                    filename="file://$(find robot_arm_description)/meshes/Center_arm_bearing_guide_clamp__1__1.stl"
                    scale="0.001 0.001 0.001" />
            </geometry>
        </collision>
    </link>

    <link name="Center_arm_bearing_guide_clamp__2__1">
        <inertial>
            <origin xyz="0.004657915250802974 -3.3420285732249644e-05 2.8375489045662228e-06"
                rpy="0 0 0" />
            <mass value="0.00032043263318911203" />
            <inertia ixx="0.0" iyy="0.0" izz="0.0" ixy="-0.0" iyz="-0.0" ixz="0.0" />
        </inertial>
        <visual>
            <origin xyz="-0.024047 -0.185049 -0.262739" rpy="0 0 0" />
            <geometry>
                <mesh
                    filename="file://$(find robot_arm_description)/meshes/Center_arm_bearing_guide_clamp__2__1.stl"
                    scale="0.001 0.001 0.001" />
            </geometry>
            <material name="silver" />
        </visual>
        <collision>
            <origin xyz="-0.024047 -0.185049 -0.262739" rpy="0 0 0" />
            <geometry>
                <mesh
                    filename="file://$(find robot_arm_description)/meshes/Center_arm_bearing_guide_clamp__2__1.stl"
                    scale="0.001 0.001 0.001" />
            </geometry>
        </collision>
    </link>

    <link name="Upper_arm_left__1__1">
        <inertial>
            <origin xyz="-0.012631449243869764 -0.030502964876164995 -1.3066627249536111e-05"
                rpy="0 0 0" />
            <mass value="0.1276460273557561" />
            <inertia ixx="0.00014" iyy="3.6e-05" izz="0.000112" ixy="0.0" iyz="-0.0" ixz="0.0" />
        </inertial>
        <visual>
            <origin xyz="0.014352 -0.185323 -0.262714" rpy="0 0 0" />
            <geometry>
                <mesh
                    filename="file://$(find robot_arm_description)/meshes/Upper_arm_left__1__1.stl"
                    scale="0.001 0.001 0.001" />
            </geometry>
            <material name="silver" />
        </visual>
        <collision>
            <origin xyz="0.014352 -0.185323 -0.262714" rpy="0 0 0" />
            <geometry>
                <mesh
                    filename="file://$(find robot_arm_description)/meshes/Upper_arm_left__1__1.stl"
                    scale="0.001 0.001 0.001" />
            </geometry>
        </collision>
    </link>

    <link name="Upper_arm_servo_mount__1__1">
        <inertial>
            <origin xyz="0.018396485302106143 0.0002904900306849867 0.009142443698116176"
                rpy="0 0 0" />
            <mass value="0.027474065783138678" />
            <inertia ixx="1.8e-05" iyy="2.2e-05" izz="5e-06" ixy="0.0" iyz="-0.0" ixz="0.0" />
        </inertial>
        <visual>
            <origin xyz="0.017269 -0.112842 -0.2627" rpy="0 0 0" />
            <geometry>
                <mesh
                    filename="file://$(find robot_arm_description)/meshes/Upper_arm_servo_mount__1__1.stl"
                    scale="0.001 0.001 0.001" />
            </geometry>
            <material name="silver" />
        </visual>
        <collision>
            <origin xyz="0.017269 -0.112842 -0.2627" rpy="0 0 0" />
            <geometry>
                <mesh
                    filename="file://$(find robot_arm_description)/meshes/Upper_arm_servo_mount__1__1.stl"
                    scale="0.001 0.001 0.001" />
            </geometry>
        </collision>
    </link>

    <link name="Upper_arm_right__1__1">
        <inertial>
            <origin xyz="0.010259204612760538 0.038729324811847585 1.2910239153729464e-05"
                rpy="0 0 0" />
            <mass value="0.10703535064188575" />
            <inertia ixx="0.000127" iyy="3.4e-05" izz="0.0001" ixy="-1e-06" iyz="-0.0" ixz="0.0" />
        </inertial>
        <visual>
            <origin xyz="-0.01953 -0.112579 -0.262724" rpy="0 0 0" />
            <geometry>
                <mesh
                    filename="file://$(find robot_arm_description)/meshes/Upper_arm_right__1__1.stl"
                    scale="0.001 0.001 0.001" />
            </geometry>
            <material name="silver" />
        </visual>
        <collision>
            <origin xyz="-0.01953 -0.112579 -0.262724" rpy="0 0 0" />
            <geometry>
                <mesh
                    filename="file://$(find robot_arm_description)/meshes/Upper_arm_right__1__1.stl"
                    scale="0.001 0.001 0.001" />
            </geometry>
        </collision>
    </link>

    <link name="MG996R_Motor_v1__1__1">
        <inertial>
            <origin xyz="-0.01119592112629058 0.004934617119766822 -0.024331590208789555"
                rpy="0 0 0" />
            <mass value="0.03924252838148347" />
            <inertia ixx="7e-06" iyy="1e-05" izz="6e-06" ixy="0.0" iyz="0.0" ixz="-0.0" />
        </inertial>
        <visual>
            <origin xyz="0.047045 0.004966 -0.159411" rpy="0 0 0" />
            <geometry>
                <mesh
                    filename="file://$(find robot_arm_description)/meshes/MG996R_Motor_v1__1__1.stl"
                    scale="0.001 0.001 0.001" />
            </geometry>
            <material name="silver" />
        </visual>
        <collision>
            <origin xyz="0.047045 0.004966 -0.159411" rpy="0 0 0" />
            <geometry>
                <mesh
                    filename="file://$(find robot_arm_description)/meshes/MG996R_Motor_v1__1__1.stl"
                    scale="0.001 0.001 0.001" />
            </geometry>
        </collision>
    </link>

    <link name="MG996R_Motor_v1__2__1">
        <inertial>
            <origin xyz="0.011075450658575625 -0.02440400759115191 -0.004847369968707216"
                rpy="0 0 0" />
            <mass value="0.03924252838148347" />
            <inertia ixx="7e-06" iyy="6e-06" izz="1e-05" ixy="0.0" iyz="-0.0" ixz="-0.0" />
        </inertial>
        <visual>
            <origin xyz="-0.040146 -0.199183 -0.267752" rpy="0 0 0" />
            <geometry>
                <mesh
                    filename="file://$(find robot_arm_description)/meshes/MG996R_Motor_v1__2__1.stl"
                    scale="0.001 0.001 0.001" />
            </geometry>
            <material name="silver" />
        </visual>
        <collision>
            <origin xyz="-0.040146 -0.199183 -0.267752" rpy="0 0 0" />
            <geometry>
                <mesh
                    filename="file://$(find robot_arm_description)/meshes/MG996R_Motor_v1__2__1.stl"
                    scale="0.001 0.001 0.001" />
            </geometry>
        </collision>
    </link>

    <link name="MG996R_Motor_v1__3__1">
        <inertial>
            <origin xyz="0.004944556467237398 0.011016364107462304 -0.02432030590875628" rpy="0 0 0" />
            <mass value="0.03924252838148347" />
            <inertia ixx="1e-05" iyy="7e-06" izz="6e-06" ixy="-0.0" iyz="0.0" ixz="0.0" />
        </inertial>
        <visual>
            <origin xyz="0.003838 -0.12024 -0.296695" rpy="0 0 0" />
            <geometry>
                <mesh
                    filename="file://$(find robot_arm_description)/meshes/MG996R_Motor_v1__3__1.stl"
                    scale="0.001 0.001 0.001" />
            </geometry>
            <material name="silver" />
        </visual>
        <collision>
            <origin xyz="0.003838 -0.12024 -0.296695" rpy="0 0 0" />
            <geometry>
                <mesh
                    filename="file://$(find robot_arm_description)/meshes/MG996R_Motor_v1__3__1.stl"
                    scale="0.001 0.001 0.001" />
            </geometry>
        </collision>
    </link>

    <link name="MG996R_Motor_v1__4__1">
        <inertial>
            <origin xyz="0.01122768652698096 -0.0049259274049419524 -0.024318960662370104"
                rpy="0 0 0" />
            <mass value="0.03924252838148347" />
            <inertia ixx="7e-06" iyy="1e-05" izz="6e-06" ixy="0.0" iyz="0.0" ixz="0.0" />
        </inertial>
        <visual>
            <origin xyz="-0.048104 -0.004355 -0.159474" rpy="0 0 0" />
            <geometry>
                <mesh
                    filename="file://$(find robot_arm_description)/meshes/MG996R_Motor_v1__4__1.stl"
                    scale="0.001 0.001 0.001" />
            </geometry>
            <material name="silver" />
        </visual>
        <collision>
            <origin xyz="-0.048104 -0.004355 -0.159474" rpy="0 0 0" />
            <geometry>
                <mesh
                    filename="file://$(find robot_arm_description)/meshes/MG996R_Motor_v1__4__1.stl"
                    scale="0.001 0.001 0.001" />
            </geometry>
        </collision>
    </link>

    <link name="MG996R_Motor_v1__5__1">
        <inertial>
            <origin xyz="0.011076138895515529 -0.02440411295257519 -0.0048467296542084315"
                rpy="0 0 0" />
            <mass value="0.03924252838148347" />
            <inertia ixx="7e-06" iyy="6e-06" izz="1e-05" ixy="0.0" iyz="-0.0" ixz="-0.0" />
        </inertial>
        <visual>
            <origin xyz="-0.039621 -0.199207 -0.150251" rpy="0 0 0" />
            <geometry>
                <mesh
                    filename="file://$(find robot_arm_description)/meshes/MG996R_Motor_v1__5__1.stl"
                    scale="0.001 0.001 0.001" />
            </geometry>
            <material name="silver" />
        </visual>
        <collision>
            <origin xyz="-0.039621 -0.199207 -0.150251" rpy="0 0 0" />
            <geometry>
                <mesh
                    filename="file://$(find robot_arm_description)/meshes/MG996R_Motor_v1__5__1.stl"
                    scale="0.001 0.001 0.001" />
            </geometry>
        </collision>
    </link>

    <link name="Cover_plate__1__1">
        <inertial>
            <origin xyz="-0.00022733948267631917 -0.03154142008480172 0.0038247065205991304"
                rpy="0 0 0" />
            <mass value="0.02728755334670412" />
            <inertia ixx="2.1e-05" iyy="4e-06" izz="2.2e-05" ixy="-0.0" iyz="3e-06" ixz="0.0" />
        </inertial>
        <visual>
            <origin xyz="-0.00107 -0.105209 -0.272711" rpy="0 0 0" />
            <geometry>
                <mesh filename="file://$(find robot_arm_description)/meshes/Cover_plate__1__1.stl"
                    scale="0.001 0.001 0.001" />
            </geometry>
            <material name="silver" />
        </visual>
        <collision>
            <origin xyz="-0.00107 -0.105209 -0.272711" rpy="0 0 0" />
            <geometry>
                <mesh filename="file://$(find robot_arm_description)/meshes/Cover_plate__1__1.stl"
                    scale="0.001 0.001 0.001" />
            </geometry>
        </collision>
    </link>

    <link name="Servo_mount__1__1">
        <inertial>
            <origin xyz="0.01139450508624097 -0.038903093526049884 -0.007916676321719829"
                rpy="0 0 0" />
            <mass value="0.029711805162689307" />
            <inertia ixx="2.4e-05" iyy="5e-06" izz="2.8e-05" ixy="-0.0" iyz="-0.0" ixz="-0.0" />
        </inertial>
        <visual>
            <origin xyz="0.010604 -0.102296 -0.251453" rpy="0 0 0" />
            <geometry>
                <mesh filename="file://$(find robot_arm_description)/meshes/Servo_mount__1__1.stl"
                    scale="0.001 0.001 0.001" />
            </geometry>
            <material name="silver" />
        </visual>
        <collision>
            <origin xyz="0.010604 -0.102296 -0.251453" rpy="0 0 0" />
            <geometry>
                <mesh filename="file://$(find robot_arm_description)/meshes/Servo_mount__1__1.stl"
                    scale="0.001 0.001 0.001" />
            </geometry>
        </collision>
    </link>

    <link name="Bearing_guide__1__1">
        <inertial>
            <origin xyz="-7.6016857537221285e-06 -2.4342218608655597e-06 0.012249906094306096"
                rpy="0 0 0" />
            <mass value="0.0020147008554729728" />
            <inertia ixx="0.0" iyy="0.0" izz="0.0" ixy="-0.0" iyz="0.0" ixz="0.0" />
        </inertial>
        <visual>
            <origin xyz="-0.00055 -0.030465 -0.251448" rpy="0 0 0" />
            <geometry>
                <mesh filename="file://$(find robot_arm_description)/meshes/Bearing_guide__1__1.stl"
                    scale="0.001 0.001 0.001" />
            </geometry>
            <material name="silver" />
        </visual>
        <collision>
            <origin xyz="-0.00055 -0.030465 -0.251448" rpy="0 0 0" />
            <geometry>
                <mesh filename="file://$(find robot_arm_description)/meshes/Bearing_guide__1__1.stl"
                    scale="0.001 0.001 0.001" />
            </geometry>
        </collision>
    </link>

    <link name="Bearing_top-bottom_bushing__2__1">
        <inertial>
            <origin xyz="-8.394335989112076e-07 -6.81810383280218e-07 0.0017499084180680469"
                rpy="0 0 0" />
            <mass value="0.0019297026707657304" />
            <inertia ixx="0.0" iyy="0.0" izz="0.0" ixy="0.0" iyz="-0.0" ixz="-0.0" />
        </inertial>
        <visual>
            <origin xyz="-0.00055 -0.030465 -0.251448" rpy="0 0 0" />
            <geometry>
                <mesh
                    filename="file://$(find robot_arm_description)/meshes/Bearing_top-bottom_bushing__2__1.stl"
                    scale="0.001 0.001 0.001" />
            </geometry>
            <material name="silver" />
        </visual>
        <collision>
            <origin xyz="-0.00055 -0.030465 -0.251448" rpy="0 0 0" />
            <geometry>
                <mesh
                    filename="file://$(find robot_arm_description)/meshes/Bearing_top-bottom_bushing__2__1.stl"
                    scale="0.001 0.001 0.001" />
            </geometry>
        </collision>
    </link>

    <link name="Bearing_center_bushing__1__1">
        <inertial>
            <origin xyz="1.1398314703919528e-05 2.5657781939809887e-06 -0.017250093905693875"
                rpy="0 0 0" />
            <mass value="0.004135077151640851" />
            <inertia ixx="0.0" iyy="0.0" izz="0.0" ixy="0.0" iyz="-0.0" ixz="-0.0" />
        </inertial>
        <visual>
            <origin xyz="-0.000531 -0.03046 -0.280948" rpy="0 0 0" />
            <geometry>
                <mesh
                    filename="file://$(find robot_arm_description)/meshes/Bearing_center_bushing__1__1.stl"
                    scale="0.001 0.001 0.001" />
            </geometry>
            <material name="silver" />
        </visual>
        <collision>
            <origin xyz="-0.000531 -0.03046 -0.280948" rpy="0 0 0" />
            <geometry>
                <mesh
                    filename="file://$(find robot_arm_description)/meshes/Bearing_center_bushing__1__1.stl"
                    scale="0.001 0.001 0.001" />
            </geometry>
        </collision>
    </link>

    <link name="Bearing_top-bottom_bushing__1__1">
        <inertial>
            <origin xyz="4.636063006737117e-06 8.133667713794424e-07 -0.006750096229455604"
                rpy="0 0 0" />
            <mass value="0.0019297026707657304" />
            <inertia ixx="0.0" iyy="0.0" izz="0.0" ixy="0.0" iyz="-0.0" ixz="-0.0" />
        </inertial>
        <visual>
            <origin xyz="-0.000531 -0.03046 -0.280948" rpy="0 0 0" />
            <geometry>
                <mesh
                    filename="file://$(find robot_arm_description)/meshes/Bearing_top-bottom_bushing__1__1.stl"
                    scale="0.001 0.001 0.001" />
            </geometry>
            <material name="silver" />
        </visual>
        <collision>
            <origin xyz="-0.000531 -0.03046 -0.280948" rpy="0 0 0" />
            <geometry>
                <mesh
                    filename="file://$(find robot_arm_description)/meshes/Bearing_top-bottom_bushing__1__1.stl"
                    scale="0.001 0.001 0.001" />
            </geometry>
        </collision>
    </link>

    <link name="Servo_gear__1__1">
        <inertial>
            <origin xyz="9.348183582290489e-06 2.8405260377728503e-06 -0.014782497790955751"
                rpy="0 0 0" />
            <mass value="0.012166533166358384" />
            <inertia ixx="1e-06" iyy="1e-06" izz="1e-06" ixy="0.0" iyz="-0.0" ixz="-0.0" />
        </inertial>
        <visual>
            <origin xyz="-0.000856 -0.075459 -0.275956" rpy="0 0 0" />
            <geometry>
                <mesh filename="file://$(find robot_arm_description)/meshes/Servo_gear__1__1.stl"
                    scale="0.001 0.001 0.001" />
            </geometry>
            <material name="silver" />
        </visual>
        <collision>
            <origin xyz="-0.000856 -0.075459 -0.275956" rpy="0 0 0" />
            <geometry>
                <mesh filename="file://$(find robot_arm_description)/meshes/Servo_gear__1__1.stl"
                    scale="0.001 0.001 0.001" />
            </geometry>
        </collision>
    </link>

    <link name="Gripper_120T__1__1">
        <inertial>
            <origin xyz="0.018088212944934335 -0.010633863240265131 0.01453826477164688" rpy="0 0 0" />
            <mass value="0.037519098370183246" />
            <inertia ixx="4.8e-05" iyy="1.1e-05" izz="5.7e-05" ixy="5e-06" iyz="3e-06" ixz="-0.0" />
        </inertial>
        <visual>
            <origin xyz="-0.000554 -0.030465 -0.246448" rpy="0 0 0" />
            <geometry>
                <mesh filename="file://$(find robot_arm_description)/meshes/Gripper_120T__1__1.stl"
                    scale="0.001 0.001 0.001" />
            </geometry>
            <material name="silver" />
        </visual>
        <collision>
            <origin xyz="-0.000554 -0.030465 -0.246448" rpy="0 0 0" />
            <geometry>
                <mesh filename="file://$(find robot_arm_description)/meshes/Gripper_120T__1__1.stl"
                    scale="0.001 0.001 0.001" />
            </geometry>
        </collision>
    </link>

    <link name="Gripper_72T__1__1">
        <inertial>
            <origin xyz="-0.017845903931154043 -0.020359999978012314 0.019763391982531464"
                rpy="0 0 0" />
            <mass value="0.029955795985461164" />
            <inertia ixx="2.3e-05" iyy="4e-06" izz="2.6e-05" ixy="-3e-06" iyz="-2e-06" ixz="-0.0" />
        </inertial>
        <visual>
            <origin xyz="-0.000554 -0.030465 -0.246448" rpy="0 0 0" />
            <geometry>
                <mesh filename="file://$(find robot_arm_description)/meshes/Gripper_72T__1__1.stl"
                    scale="0.001 0.001 0.001" />
            </geometry>
            <material name="silver" />
        </visual>
        <collision>
            <origin xyz="-0.000554 -0.030465 -0.246448" rpy="0 0 0" />
            <geometry>
                <mesh filename="file://$(find robot_arm_description)/meshes/Gripper_72T__1__1.stl"
                    scale="0.001 0.001 0.001" />
            </geometry>
        </collision>
    </link>

    <link name="MG996R_Motor_v1__4___1__1">
        <inertial>
            <origin xyz="-0.004669143405417471 0.024361551980028047 -0.011245760322390386"
                rpy="0 0 0" />
            <mass value="0.03924252838148347" />
            <inertia ixx="1e-05" iyy="6e-06" izz="7e-06" ixy="-0.0" iyz="0.0" ixz="0.0" />
        </inertial>
        <visual>
            <origin xyz="-0.005635 -0.040931 -0.236453" rpy="0 0 0" />
            <geometry>
                <mesh
                    filename="file://$(find robot_arm_description)/meshes/MG996R_Motor_v1__4___1__1.stl"
                    scale="0.001 0.001 0.001" />
            </geometry>
            <material name="silver" />
        </visual>
        <collision>
            <origin xyz="-0.005635 -0.040931 -0.236453" rpy="0 0 0" />
            <geometry>
                <mesh
                    filename="file://$(find robot_arm_description)/meshes/MG996R_Motor_v1__4___1__1.stl"
                    scale="0.001 0.001 0.001" />
            </geometry>
        </collision>
    </link>

    <joint name="Rigid 1" type="fixed">
        <origin xyz="-0.000112 -2.5e-05 0.010138" rpy="0 0 0" />
        <parent link="base_link" />
        <child link="Base_bottom_1" />
    </joint>

    <joint name="Rigid 2" type="fixed">
        <origin xyz="-1e-05 -3e-06 0.015" rpy="0 0 0" />
        <parent link="Base_bottom_1" />
        <child link="Base_cylinder_1" />
    </joint>

    <joint name="Rigid 3" type="fixed">
        <origin xyz="-2.6e-05 -6e-06 0.04" rpy="0 0 0" />
        <parent link="Base_cylinder_1" />
        <child link="Base_top_1" />
    </joint>

    <joint name="Rigid 4" type="fixed">
        <origin xyz="-6e-06 -2e-06 0.01" rpy="0 0 0" />
        <parent link="Base_top_1" />
        <child link="Bearing_clamp_1" />
    </joint>

    <joint name="Rigid 5" type="fixed">
        <origin xyz="-2e-06 0.0 0.0035" rpy="0 0 0" />
        <parent link="Bearing_clamp_1" />
        <child link="Bearing_ring_1" />
    </joint>

    <joint name="Rigid 6" type="fixed">
        <origin xyz="-0.047965 0.009215 0.00997" rpy="0 0 0" />
        <parent link="Base_top_1" />
        <child link="Gear_12T_1" />
    </joint>

    <joint name="Rigid 7" type="fixed">
        <origin xyz="0.04055 0.012315 0.010028" rpy="0 0 0" />
        <parent link="Base_top_1" />
        <child link="Gear_27T_1" />
    </joint>

    <joint name="Rigid 8" type="fixed">
        <origin xyz="-3.7e-05 -0.008999 -0.005001" rpy="0 0 0" />
        <parent link="Gear_12T_1" />
        <child link="Potentiometer_1" />
    </joint>

    <joint name="Rigid 9" type="fixed">
        <origin xyz="0.055598 0.040012 0.001097" rpy="0 0 0" />
        <parent link="Bearing_ring_1" />
        <child link="Steel_ball_10mm_1" />
    </joint>

    <joint name="Rigid 10" type="fixed">
        <origin xyz="0.021461 0.06505 0.001079" rpy="0 0 0" />
        <parent link="Bearing_ring_1" />
        <child link="Steel_ball_10mm_4" />
    </joint>

    <joint name="Rigid 11" type="fixed">
        <origin xyz="-0.020874 0.065242 0.001052" rpy="0 0 0" />
        <parent link="Bearing_ring_1" />
        <child link="Steel_ball_10mm_3" />
    </joint>

    <joint name="Rigid 12" type="fixed">
        <origin xyz="-0.055236 0.040513 0.001026" rpy="0 0 0" />
        <parent link="Bearing_ring_1" />
        <child link="Steel_ball_10mm_2" />
    </joint>

    <joint name="Rigid 13" type="fixed">
        <origin xyz="-0.0685 0.000309 0.00101" rpy="0 0 0" />
        <parent link="Bearing_ring_1" />
        <child link="Steel_ball_10mm_10" />
    </joint>

    <joint name="Rigid 14" type="fixed">
        <origin xyz="0.068498 -0.00031 0.001098" rpy="0 0 0" />
        <parent link="Bearing_ring_1" />
        <child link="Steel_ball_10mm_9" />
    </joint>

    <joint name="Rigid 15" type="fixed">
        <origin xyz="0.055234 -0.040514 0.001083" rpy="0 0 0" />
        <parent link="Bearing_ring_1" />
        <child link="Steel_ball_10mm_8" />
    </joint>

    <joint name="Rigid 16" type="fixed">
        <origin xyz="0.020872 -0.065243 0.001057" rpy="0 0 0" />
        <parent link="Bearing_ring_1" />
        <child link="Steel_ball_10mm_5" />
    </joint>

    <joint name="Rigid 17" type="fixed">
        <origin xyz="-0.021463 -0.065052 0.00103" rpy="0 0 0" />
        <parent link="Bearing_ring_1" />
        <child link="Steel_ball_10mm_6" />
    </joint>

    <joint name="Rigid 18" type="fixed">
        <origin xyz="-0.0556 -0.040013 0.001012" rpy="0 0 0" />
        <parent link="Bearing_ring_1" />
        <child link="Steel_ball_10mm_7" />
    </joint>

    <joint name="Rigid 19" type="fixed">
        <origin xyz="0.0 0.0 0.0" rpy="0 0 0" />
        <parent link="Base_bottom_1" />
        <child link="Bearing_clamp_2" />
    </joint>

    <joint name="Revolute_20" type="continuous">
        <origin xyz="-1e-06 -1e-06 0.001054" rpy="0 0 0" />
        <parent link="Bearing_ring_1" />
        <child link="Rotating_plate_1" />
        <axis xyz="-0.000644 -0.000167 1.0" />
        <limit effort="100" velocity="1.5" />
    </joint>

    <joint name="Rigid 21" type="fixed">
        <origin xyz="4.3e-05 1.1e-05 -0.0665" rpy="0 0 0" />
        <parent link="Rotating_plate_1" />
        <child link="Rotating_plate_clamp_1" />
    </joint>

    <joint name="Rigid 24" type="fixed">
        <origin xyz="-0.039411 -0.013347 0.022473" rpy="0 0 0" />
        <parent link="Rotating_plate_1" />
        <child link="Base_servo_mount_1" />
    </joint>

    <joint name="Rigid 25" type="fixed">
        <origin xyz="0.007568 0.013314 0.043007" rpy="0 0 0" />
        <parent link="Base_servo_mount_1" />
        <child link="Base_servo_mount__1__1" />
    </joint>

    <joint name="Revolute_26" type="revolute">
        <origin xyz="0.007568 0.013314 0.043007" rpy="0 0 0" />
        <parent link="Base_servo_mount_1" />
        <child link="Lower_arm_left_1" />
        <axis xyz="0.999974 -0.007141 0.000643" />
        <limit upper="3.141593" lower="0.0" effort="100" velocity="100" />
    </joint>

    <joint name="Rigid 27" type="fixed">
        <origin xyz="0.013403 0.000439 9e-06" rpy="0 0 0" />
        <parent link="Lower_arm_left_1" />
        <child link="Lower_arm_right_1" />
    </joint>

    <joint name="Rigid 28" type="fixed">
        <origin xyz="0.01426 0.120436 2.9e-05" rpy="0 0 0" />
        <parent link="Lower_arm_left_1" />
        <child link="Lower_arm_bushing__1__1" />
    </joint>

    <joint name="Rigid 29" type="fixed">
        <origin xyz="0.013867 0.065437 2e-05" rpy="0 0 0" />
        <parent link="Lower_arm_left_1" />
        <child link="Lower_arm_bushing_1" />
    </joint>

    <joint name="Revolute_30" type="revolute">
        <origin xyz="0.014724 0.185434 4e-05" rpy="0 0 0" />
        <parent link="Lower_arm_left_1" />
        <child link="Center_arm_1" />
        <axis xyz="0.999974 -0.007141 0.000643" />
        <limit upper="0.0" lower="-2.617994" effort="100" velocity="100" />
    </joint>

    <joint name="Rigid 31" type="fixed">
        <origin xyz="0.027999 -0.0002 1.8e-05" rpy="0 0 0" />
        <parent link="Center_arm_1" />
        <child link="Center_arm_bearing_guide__1__1" />
    </joint>

    <joint name="Rigid 32" type="fixed">
        <origin xyz="0.0134 -9.6e-05 9e-06" rpy="0 0 0" />
        <parent link="Center_arm_bearing_guide__1__1" />
        <child link="Bearing_holder_1" />
    </joint>

    <joint name="Rigid 33" type="fixed">
        <origin xyz="0.027924 -0.000219 0.117518" rpy="0 0 0" />
        <parent link="Center_arm_1" />
        <child link="Center_arm_bearing_guide_1" />
    </joint>

    <joint name="Rigid 34" type="fixed">
        <origin xyz="0.013399 -9.6e-05 9e-06" rpy="0 0 0" />
        <parent link="Center_arm_bearing_guide_1" />
        <child link="Bearing_holder__1__1" />
    </joint>

    <joint name="Rigid 35" type="fixed">
        <origin xyz="0.0084 -6e-05 5e-06" rpy="0 0 0" />
        <parent link="Bearing_holder_1" />
        <child link="Center_arm_bearing_guide_clamp__1__1" />
    </joint>

    <joint name="Rigid 36" type="fixed">
        <origin xyz="0.013399 -9.6e-05 9e-06" rpy="0 0 0" />
        <parent link="Center_arm_bearing_guide_1" />
        <child link="Center_arm_bearing_guide_clamp__2__1" />
    </joint>

    <joint name="Revolute_37" type="revolute">
        <origin xyz="0.002924 -4.1e-05 0.117502" rpy="0 0 0" />
        <parent link="Center_arm_1" />
        <child link="Upper_arm_left__1__1" />
        <axis xyz="-0.999974 0.007141 -0.000643" />
        <limit upper="1.570796" lower="-0.349066" effort="100" velocity="100" />
    </joint>

    <joint name="Rigid 38" type="fixed">
        <origin xyz="-0.002917 -0.072481 -1.4e-05" rpy="0 0 0" />
        <parent link="Upper_arm_left__1__1" />
        <child link="Upper_arm_servo_mount__1__1" />
    </joint>

    <joint name="Rigid 39" type="fixed">
        <origin xyz="0.036799 -0.000263 2.4e-05" rpy="0 0 0" />
        <parent link="Upper_arm_servo_mount__1__1" />
        <child link="Upper_arm_right__1__1" />
    </joint>

    <joint name="Rigid 40" type="fixed">
        <origin xyz="-0.007477 0.008418 0.057246" rpy="0 0 0" />
        <parent link="Base_servo_mount_1" />
        <child link="MG996R_Motor_v1__1__1" />
    </joint>

    <joint name="Rigid 41" type="fixed">
        <origin xyz="0.020616 0.086604 0.005028" rpy="0 0 0" />
        <parent link="Upper_arm_right__1__1" />
        <child link="MG996R_Motor_v1__2__1" />
    </joint>

    <joint name="Rigid 42" type="fixed">
        <origin xyz="0.013431 0.007398 0.033995" rpy="0 0 0" />
        <parent link="Upper_arm_servo_mount__1__1" />
        <child link="MG996R_Motor_v1__3__1" />
    </joint>

    <joint name="Rigid 43" type="fixed">
        <origin xyz="0.080104 0.004425 0.014302" rpy="0 0 0" />
        <parent link="Base_servo_mount__1__1" />
        <child link="MG996R_Motor_v1__4__1" />
    </joint>

    <joint name="Rigid 44" type="fixed">
        <origin xyz="0.058218 0.198838 0.00507" rpy="0 0 0" />
        <parent link="Lower_arm_right_1" />
        <child link="MG996R_Motor_v1__5__1" />
    </joint>

    <joint name="Revolute_45" type="revolute">
        <origin xyz="0.018339 -0.007633 0.010011" rpy="0 0 0" />
        <parent link="Upper_arm_servo_mount__1__1" />
        <child link="Cover_plate__1__1" />
        <axis xyz="-0.00714 -0.999974 -0.000171" />
        <limit upper="0.785398" lower="-0.785398" effort="100" velocity="100" />
    </joint>

    <joint name="Rigid 46" type="fixed">
        <origin xyz="-0.011674 -0.002913 -0.021258" rpy="0 0 0" />
        <parent link="Cover_plate__1__1" />
        <child link="Servo_mount__1__1" />
    </joint>

    <joint name="Rigid 49" type="fixed">
        <origin xyz="0.011154 -0.071831 -5e-06" rpy="0 0 0" />
        <parent link="Servo_mount__1__1" />
        <child link="Bearing_guide__1__1" />
    </joint>

    <joint name="Rigid 50" type="fixed">
        <origin xyz="0.011154 -0.071831 -5e-06" rpy="0 0 0" />
        <parent link="Servo_mount__1__1" />
        <child link="Bearing_top-bottom_bushing__2__1" />
    </joint>

    <joint name="Rigid 52" type="fixed">
        <origin xyz="-1.9e-05 -5e-06 0.0295" rpy="0 0 0" />
        <parent link="Bearing_guide__1__1" />
        <child link="Bearing_center_bushing__1__1" />
    </joint>

    <joint name="Rigid 54" type="fixed">
        <origin xyz="-1.9e-05 -5e-06 0.0295" rpy="0 0 0" />
        <parent link="Bearing_guide__1__1" />
        <child link="Bearing_top-bottom_bushing__1__1" />
    </joint>

    <joint name="Rigid 59" type="fixed">
        <origin xyz="-0.000214 -0.02975 0.003245" rpy="0 0 0" />
        <parent link="Cover_plate__1__1" />
        <child link="Servo_gear__1__1" />
    </joint>

    <joint name="Revolute_60" type="revolute">
        <origin xyz="4e-06 0.0 -0.005" rpy="0 0 0" />
        <parent link="Bearing_guide__1__1" />
        <child link="Gripper_120T__1__1" />
        <axis xyz="0.000644 0.000167 -1.0" />
        <limit upper="0.0" lower="-0.785398" effort="100" velocity="100" />
    </joint>

    <joint name="Revolute_61" type="revolute">
        <origin xyz="4e-06 0.0 -0.005" rpy="0 0 0" />
        <parent link="Bearing_guide__1__1" />
        <child link="Gripper_72T__1__1" />
        <axis xyz="-0.000644 -0.000167 1.0" />
        <limit upper="0.0" lower="-0.785398" effort="100" velocity="100" />
        <mimic joint="Revolute_60" multiplier="1.0" /> 
    </joint>

    <joint name="Rigid 62" type="fixed">
        <origin xyz="0.016239 -0.061365 -0.015" rpy="0 0 0" />
        <parent link="Servo_mount__1__1" />
        <child link="MG996R_Motor_v1__4___1__1" />
    </joint>

</robot>