<?xml version="1.0"?>
<robot name="base" xmlns:xacro="http://www.ros.org/wiki/xacro">

    <xacro:include filename="$(find base_description)/urdf/materials.xacro" />
    <xacro:include filename="$(find base_description)/urdf/base.trans" />
    <xacro:include filename="$(find base_description)/urdf/base.gazebo" />
    <link name="base_link">
        <inertial>
            <origin xyz="-0.0395707019946801 0.004107393751103468 0.16958490409411905" rpy="0 0 0" />
            <mass value="31.97041974806837" />
            <inertia ixx="0.987054" iyy="1.498873" izz="1.382345" ixy="-0.0" iyz="1e-06"
                ixz="0.323526" />
        </inertial>
        <visual>
            <origin xyz="0 0 0" rpy="0 0 0" />
            <geometry>
                <mesh filename="package://base_description/meshes/base_link.stl"
                    scale="0.001 0.001 0.001" />
            </geometry>
            <material name="military_green" />
        </visual>
        <collision>
            <origin xyz="0 0 0" rpy="0 0 0" />
            <geometry>
                <mesh filename="package://base_description/meshes/base_link.stl"
                    scale="0.001 0.001 0.001" />
            </geometry>
        </collision>
    </link>

    <link name="left_front_wheel_1">
        <inertial>
            <origin xyz="0.06491952306333931 2.713483924221549e-07 -9.871360775876026e-07"
                rpy="0 0 0" />
            <mass value="1.7279014792962415" />
            <inertia ixx="0.007189" iyy="0.0043" izz="0.004301" ixy="-0.0" iyz="-0.0" ixz="0.0" />
        </inertial>
        <visual>
            <origin xyz="-0.196088 -0.176604 -0.0974" rpy="0 0 0" />
            <geometry>
                <mesh filename="package://base_description/meshes/left_front_wheel_1.stl"
                    scale="0.001 0.001 0.001" />
            </geometry>
            <material name="black" />
        </visual>
        <collision>
            <origin xyz="-0.196088 -0.176604 -0.0974" rpy="0 0 0" />
            <geometry>
                <mesh filename="package://base_description/meshes/left_front_wheel_1.stl"
                    scale="0.001 0.001 0.001" />
            </geometry>
        </collision>
    </link>

    <link name="left_back_wheel_1">
        <inertial>
            <origin xyz="-8.10576490095638e-07 0.06491980090724014 2.71348391173154e-07" rpy="0 0 0" />
            <mass value="1.7279014792962415" />
            <inertia ixx="0.004301" iyy="0.007189" izz="0.0043" ixy="0.0" iyz="-0.0" ixz="-0.0" />
        </inertial>
        <visual>
            <origin xyz="0.203912 -0.176604 -0.0974" rpy="0 0 0" />
            <geometry>
                <mesh filename="package://base_description/meshes/left_back_wheel_1.stl"
                    scale="0.001 0.001 0.001" />
            </geometry>
            <material name="black" />
        </visual>
        <collision>
            <origin xyz="0.203912 -0.176604 -0.0974" rpy="0 0 0" />
            <geometry>
                <mesh filename="package://base_description/meshes/left_back_wheel_1.stl"
                    scale="0.001 0.001 0.001" />
            </geometry>
        </collision>
    </link>
    
    <link name="right_back_wheel_1">
        <inertial>
            <origin xyz="-8.10576483295522e-07 -0.06491934650373041 -2.7134839501730124e-07"
                rpy="0 0 0" />
            <mass value="1.7279014792962415" />
            <inertia ixx="0.004301" iyy="0.007189" izz="0.0043" ixy="-0.0" iyz="-0.0" ixz="0.0" />
        </inertial>
        <visual>
            <origin xyz="0.203912 0.168396 -0.0974" rpy="0 0 0" />
            <geometry>
                <mesh filename="package://base_description/meshes/right_back_wheel_1.stl"
                    scale="0.001 0.001 0.001" />
            </geometry>
            <material name="black" />
        </visual>
        <collision>
            <origin xyz="0.203912 0.168396 -0.0974" rpy="0 0 0" />
            <geometry>
                <mesh filename="package://base_description/meshes/right_back_wheel_1.stl"
                    scale="0.001 0.001 0.001" />
            </geometry>
        </collision>
    </link>

    <link name="right_front_wheel_1">
        <inertial>
            <origin xyz="-6.980775361653535e-07 -0.06491934650373232 -5.320502585309805e-07"
                rpy="0 0 0" />
            <mass value="1.7279014792962415" />
            <inertia ixx="0.0043" iyy="0.007189" izz="0.0043" ixy="-0.0" iyz="-0.0" ixz="0.0" />
        </inertial>
        <visual>
            <origin xyz="-0.196088 0.168396 -0.0974" rpy="0 0 0" />
            <geometry>
                <mesh filename="package://base_description/meshes/right_front_wheel_1.stl"
                    scale="0.001 0.001 0.001" />
            </geometry>
            <material name="black" />
        </visual>
        <collision>
            <origin xyz="-0.196088 0.168396 -0.0974" rpy="0 0 0" />
            <geometry>
                <mesh filename="package://base_description/meshes/right_front_wheel_1.stl"
                    scale="0.001 0.001 0.001" />
            </geometry>
        </collision>
    </link>

    <link name="oakd_lite_1">
        <inertial>
            <origin xyz="0.005627463466106791 0.00020856499505239254 -0.014899601468930102"
                rpy="0 0 0" />
            <mass value="0.14692131388829874" />
            <inertia ixx="0.000116" iyy="1.5e-05" izz="0.00011" ixy="0.0" iyz="0.0" ixz="0.0" />
        </inertial>
        <visual>
            <origin xyz="0.204016 -0.004104 -0.671703" rpy="0 0 0" />
            <geometry>
                <mesh filename="package://base_description/meshes/oakd_lite_1.stl"
                    scale="0.001 0.001 0.001" />
            </geometry>
            <material name="dark_grey" />
        </visual>
        <collision>
            <origin xyz="0.204016 -0.004104 -0.671703" rpy="0 0 0" />
            <geometry>
                <mesh filename="package://base_description/meshes/oakd_lite_1.stl"
                    scale="0.001 0.001 0.001" />
            </geometry>
        </collision>
    </link>

    <joint name="left_front_wheel_joint" type="continuous">
        <origin xyz="0.196088 0.176604 0.0974" rpy="0 0 0" />
        <parent link="base_link" />
        <child link="left_front_wheel_1" />
        <axis xyz="0.0 1.0 0.0" />
    </joint>

    <joint name="left_back_wheel_joint" type="continuous">
        <origin xyz="-0.203912 0.176604 0.0974" rpy="0 0 0" />
        <parent link="base_link" />
        <child link="left_back_wheel_1" />
        <axis xyz="0.0 1.0 0.0" />
    </joint>

    <joint name="right_back_wheel_joint" type="continuous">
        <origin xyz="-0.203912 -0.168396 0.0974" rpy="0 0 0" />
        <parent link="base_link" />
        <child link="right_back_wheel_1" />
        <axis xyz="0.0 1.0 0.0" />
    </joint>

    <joint name="right_front_wheel_joint" type="continuous">
        <origin xyz="0.196088 -0.168396 0.0974" rpy="0 0 0" />
        <parent link="base_link" />
        <child link="right_front_wheel_1" />
        <axis xyz="0.0 1.0 0.0" />
    </joint>

    <joint name="oakd_lite_joint" type="fixed">
        <origin xyz="-0.204016 0.004104 0.671703" rpy="0 0 0" />
        <parent link="base_link" />
        <child link="oakd_lite_1" />
    </joint>

</robot>