<?xml version="1.0"?>
<robot name="cika" xmlns:xacro="http://www.ros.org/wiki/xacro">

    <xacro:include filename="$(find cika_description)/urdf/materials.xacro" />
    <xacro:include filename="$(find cika_description)/urdf/cika.trans" />
    <xacro:include filename="$(find cika_description)/urdf/cika.gazebo" />
    <link name="base_link">
        <inertial>
            <origin xyz="-0.33260926446179306 0.15120963934333517 0.1740750380233756" rpy="0 0 0" />
            <mass value="30.109135104763638" />
            <inertia ixx="0.935033" iyy="1.442245" izz="1.317153" ixy="-0.016969" iyz="-0.001673"
                ixz="0.3152" />
        </inertial>
        <visual>
            <origin xyz="0 0 0" rpy="0 0 0" />
            <geometry>
                <mesh filename="file://$(find cika_description)/meshes/base_link.stl"
                    scale="0.001 0.001 0.001" />
            </geometry>
            <material name="silver" />
        </visual>
        <collision>
            <origin xyz="0 0 0" rpy="0 0 0" />
            <geometry>
                <mesh filename="file://$(find cika_description)/meshes/base_link.stl"
                    scale="0.001 0.001 0.001" />
            </geometry>
        </collision>
    </link>

    <link name="left_front_wheel_1">
        <inertial>
            <origin xyz="6.338714178544258e-07 0.06491939586512047 3.96591748746955e-08" rpy="0 0 0" />
            <mass value="1.7279014792962415" />
            <inertia ixx="0.004301" iyy="0.007189" izz="0.0043" ixy="-0.0" iyz="0.0" ixz="-0.0" />
        </inertial>
        <visual>
            <origin xyz="0.100089 -0.332003 -0.0962" rpy="0 0 0" />
            <geometry>
                <mesh filename="file://$(find cika_description)/meshes/left_front_wheel_1.stl"
                    scale="0.001 0.001 0.001" />
            </geometry>
            <material name="silver" />
        </visual>
        <collision>
            <origin xyz="0.100089 -0.332003 -0.0962" rpy="0 0 0" />
            <geometry>
                <mesh filename="file://$(find cika_description)/meshes/left_front_wheel_1.stl"
                    scale="0.001 0.001 0.001" />
            </geometry>
        </collision>
    </link>

    <link name="left_back_wheel_1">
        <inertial>
            <origin xyz="-4.926971846064276e-07 0.06491939586511769 -6.76128510235241e-07"
                rpy="0 0 0" />
            <mass value="1.7279014792962415" />
            <inertia ixx="0.0043" iyy="0.007189" izz="0.004301" ixy="0.0" iyz="0.0" ixz="0.0" />
        </inertial>
        <visual>
            <origin xyz="0.47736 -0.332003 -0.0962" rpy="0 0 0" />
            <geometry>
                <mesh filename="file://$(find cika_description)/meshes/left_back_wheel_1.stl"
                    scale="0.001 0.001 0.001" />
            </geometry>
            <material name="silver" />
        </visual>
        <collision>
            <origin xyz="0.47736 -0.332003 -0.0962" rpy="0 0 0" />
            <geometry>
                <mesh filename="file://$(find cika_description)/meshes/left_back_wheel_1.stl"
                    scale="0.001 0.001 0.001" />
            </geometry>
        </collision>
    </link>

    <link name="right_front_wheel_1">
        <inertial>
            <origin xyz="6.50511300104295e-07 -0.06491983576316293 8.338073121116896e-07"
                rpy="0 0 0" />
            <mass value="1.7278807706707637" />
            <inertia ixx="0.0043" iyy="0.007189" izz="0.0043" ixy="0.0" iyz="0.0" ixz="0.0" />
        </inertial>
        <visual>
            <origin xyz="0.099911 0.031017 -0.0962" rpy="0 0 0" />
            <geometry>
                <mesh filename="file://$(find cika_description)/meshes/right_front_wheel_1.stl"
                    scale="0.001 0.001 0.001" />
            </geometry>
            <material name="silver" />
        </visual>
        <collision>
            <origin xyz="0.099911 0.031017 -0.0962" rpy="0 0 0" />
            <geometry>
                <mesh filename="file://$(find cika_description)/meshes/right_front_wheel_1.stl"
                    scale="0.001 0.001 0.001" />
            </geometry>
        </collision>
    </link>

    <link name="right_back_wheel_1">
        <inertial>
            <origin xyz="-5.185954176090135e-07 -0.06491983576315802 -2.1179218925859722e-07"
                rpy="0 0 0" />
            <mass value="1.7278807706707027" />
            <inertia ixx="0.0043" iyy="0.007189" izz="0.0043" ixy="-0.0" iyz="-0.0" ixz="0.0" />
        </inertial>
        <visual>
            <origin xyz="0.47736 0.030997 -0.0962" rpy="0 0 0" />
            <geometry>
                <mesh filename="file://$(find cika_description)/meshes/right_back_wheel_1.stl"
                    scale="0.001 0.001 0.001" />
            </geometry>
            <material name="silver" />
        </visual>
        <collision>
            <origin xyz="0.47736 0.030997 -0.0962" rpy="0 0 0" />
            <geometry>
                <mesh filename="file://$(find cika_description)/meshes/right_back_wheel_1.stl"
                    scale="0.001 0.001 0.001" />
            </geometry>
        </collision>
    </link>

    <link name="lidar_1">
        <inertial>
            <origin xyz="-7.788860805083703e-05 1.0901727409695638e-08 0.018461743261943914"
                rpy="0 0 0" />
            <mass value="0.13019242629948757" />
            <inertia ixx="4.5e-05" iyy="4.5e-05" izz="5.5e-05" ixy="-0.0" iyz="0.0" ixz="-0.0" />
        </inertial>
        <visual>
            <origin xyz="0.038004 -0.265503 -0.193866" rpy="0 0 0" />
            <geometry>
                <mesh filename="file://$(find cika_description)/meshes/lidar_1.stl"
                    scale="0.001 0.001 0.001" />
            </geometry>
            <material name="silver" />
        </visual>
        <collision>
            <origin xyz="0.038004 -0.265503 -0.193866" rpy="0 0 0" />
            <geometry>
                <mesh filename="file://$(find cika_description)/meshes/lidar_1.stl"
                    scale="0.001 0.001 0.001" />
            </geometry>
        </collision>
    </link>

    <link name="OAKDcamera_1">
        <inertial>
            <origin xyz="0.008627287459209043 0.000208170161947685 0.00010063024921169728"
                rpy="0 0 0" />
            <mass value="0.1469212855023488" />
            <inertia ixx="0.000116" iyy="1.5e-05" izz="0.00011" ixy="0.0" iyz="0.0" ixz="0.0" />
        </inertial>
        <visual>
            <origin xyz="0.517714 -0.150503 -0.657116" rpy="0 0 0" />
            <geometry>
                <mesh filename="file://$(find cika_description)/meshes/OAKDcamera_1.stl"
                    scale="0.001 0.001 0.001" />
            </geometry>
            <material name="silver" />
        </visual>
        <collision>
            <origin xyz="0.517714 -0.150503 -0.657116" rpy="0 0 0" />
            <geometry>
                <mesh filename="file://$(find cika_description)/meshes/OAKDcamera_1.stl"
                    scale="0.001 0.001 0.001" />
            </geometry>
        </collision>
    </link>

    <link name="arm_bottom_1">
        <inertial>
            <origin xyz="-0.054909370312956396 -0.0007071460484354419 0.03829370665229939"
                rpy="0 0 0" />
            <mass value="0.8582742343668851" />
            <inertia ixx="0.002214" iyy="0.002209" izz="0.003262" ixy="-5e-06" iyz="-4e-06"
                ixz="1e-06" />
        </inertial>
        <visual>
            <origin xyz="0.069976 -0.15041 -0.149616" rpy="0 0 0" />
            <geometry>
                <mesh filename="file://$(find cika_description)/meshes/arm_bottom_1.stl"
                    scale="0.001 0.001 0.001" />
            </geometry>
            <material name="silver" />
        </visual>
        <collision>
            <origin xyz="0.069976 -0.15041 -0.149616" rpy="0 0 0" />
            <geometry>
                <mesh filename="file://$(find cika_description)/meshes/arm_bottom_1.stl"
                    scale="0.001 0.001 0.001" />
            </geometry>
        </collision>
    </link>

    <link name="turntable_1">
        <inertial>
            <origin xyz="0.0001872362428069485 0.00027238134309487405 0.030410920566191824"
                rpy="0 0 0" />
            <mass value="0.5193886148387532" />
            <inertia ixx="0.001399" iyy="0.000986" izz="0.001632" ixy="1e-06" iyz="-4e-06"
                ixz="-0.0" />
        </inertial>
        <visual>
            <origin xyz="0.124976 -0.15041 -0.229171" rpy="0 0 0" />
            <geometry>
                <mesh filename="file://$(find cika_description)/meshes/turntable_1.stl"
                    scale="0.001 0.001 0.001" />
            </geometry>
            <material name="silver" />
        </visual>
        <collision>
            <origin xyz="0.124976 -0.15041 -0.229171" rpy="0 0 0" />
            <geometry>
                <mesh filename="file://$(find cika_description)/meshes/turntable_1.stl"
                    scale="0.001 0.001 0.001" />
            </geometry>
        </collision>
    </link>

    <link name="lower_arm_1">
        <inertial>
            <origin xyz="-0.09815269472471186 0.034884892502197146 -0.013436087195066948"
                rpy="0 0 0" />
            <mass value="0.6297893688817031" />
            <inertia ixx="0.000792" iyy="0.002646" izz="0.002968" ixy="0.000116" iyz="1.6e-05"
                ixz="-0.000303" />
        </inertial>
        <visual>
            <origin xyz="0.124726 -0.11861 -0.294671" rpy="0 0 0" />
            <geometry>
                <mesh filename="file://$(find cika_description)/meshes/lower_arm_1.stl"
                    scale="0.001 0.001 0.001" />
            </geometry>
            <material name="silver" />
        </visual>
        <collision>
            <origin xyz="0.124726 -0.11861 -0.294671" rpy="0 0 0" />
            <geometry>
                <mesh filename="file://$(find cika_description)/meshes/lower_arm_1.stl"
                    scale="0.001 0.001 0.001" />
            </geometry>
        </collision>
    </link>

    <link name="center_arm_1">
        <inertial>
            <origin xyz="-0.022216695907628425 -0.022792061476347353 0.054595767734493705"
                rpy="0 0 0" />
            <mass value="0.3101540991150054" />
            <inertia ixx="0.000639" iyy="0.000774" izz="0.000187" ixy="3e-06" iyz="-6e-06"
                ixz="0.000223" />
        </inertial>
        <visual>
            <origin xyz="0.308014 -0.17411 -0.269563" rpy="0 0 0" />
            <geometry>
                <mesh filename="file://$(find cika_description)/meshes/center_arm_1.stl"
                    scale="0.001 0.001 0.001" />
            </geometry>
            <material name="silver" />
        </visual>
        <collision>
            <origin xyz="0.308014 -0.17411 -0.269563" rpy="0 0 0" />
            <geometry>
                <mesh filename="file://$(find cika_description)/meshes/center_arm_1.stl"
                    scale="0.001 0.001 0.001" />
            </geometry>
        </collision>
    </link>

    <link name="upper_arm_1">
        <inertial>
            <origin xyz="0.03416739959858034 -0.025827383064131765 -0.00858731456153955" rpy="0 0 0" />
            <mass value="0.34058866178884734" />
            <inertia ixx="0.000398" iyy="0.000385" izz="0.000585" ixy="3.6e-05" iyz="-8e-06"
                ixz="4.3e-05" />
        </inertial>
        <visual>
            <origin xyz="0.353547 -0.18061 -0.377882" rpy="0 0 0" />
            <geometry>
                <mesh filename="file://$(find cika_description)/meshes/upper_arm_1.stl"
                    scale="0.001 0.001 0.001" />
            </geometry>
            <material name="silver" />
        </visual>
        <collision>
            <origin xyz="0.353547 -0.18061 -0.377882" rpy="0 0 0" />
            <geometry>
                <mesh filename="file://$(find cika_description)/meshes/upper_arm_1.stl"
                    scale="0.001 0.001 0.001" />
            </geometry>
        </collision>
    </link>

    <link name="gripper_mount_1">
        <inertial>
            <origin xyz="0.03518522031420046 4.947466888538532e-05 -0.02649281738910253" rpy="0 0 0" />
            <mass value="0.11840999912096761" />
            <inertia ixx="6.5e-05" iyy="0.00012" izz="7.2e-05" ixy="0.0" iyz="0.0" ixz="3e-06" />
        </inertial>
        <visual>
            <origin xyz="0.272519 -0.15066 -0.373681" rpy="0 0 0" />
            <geometry>
                <mesh filename="file://$(find cika_description)/meshes/gripper_mount_1.stl"
                    scale="0.001 0.001 0.001" />
            </geometry>
            <material name="silver" />
        </visual>
        <collision>
            <origin xyz="0.272519 -0.15066 -0.373681" rpy="0 0 0" />
            <geometry>
                <mesh filename="file://$(find cika_description)/meshes/gripper_mount_1.stl"
                    scale="0.001 0.001 0.001" />
            </geometry>
        </collision>
    </link>

    <link name="left_gripper_1">
        <inertial>
            <origin xyz="0.00925802340474019 0.018173289845735685 -0.0056566853453800525"
                rpy="0 0 0" />
            <mass value="0.037519098370183246" />
            <inertia ixx="1.3e-05" iyy="4.8e-05" izz="5.5e-05" ixy="-5e-06" iyz="1e-06" ixz="1e-05" />
        </inertial>
        <visual>
            <origin xyz="0.200041 -0.15066 -0.35166" rpy="0 0 0" />
            <geometry>
                <mesh filename="file://$(find cika_description)/meshes/left_gripper_1.stl"
                    scale="0.001 0.001 0.001" />
            </geometry>
            <material name="silver" />
        </visual>
        <collision>
            <origin xyz="0.200041 -0.15066 -0.35166" rpy="0 0 0" />
            <geometry>
                <mesh filename="file://$(find cika_description)/meshes/left_gripper_1.stl"
                    scale="0.001 0.001 0.001" />
            </geometry>
        </collision>
    </link>

    <link name="right_gripper_1">
        <inertial>
            <origin xyz="0.020334687343400326 -0.017687094901279954 -0.0035351840699497927"
                rpy="0 0 0" />
            <mass value="0.029955795985461164" />
            <inertia ixx="7e-06" iyy="2.3e-05" izz="2.3e-05" ixy="2e-06" iyz="-1e-06" ixz="8e-06" />
        </inertial>
        <visual>
            <origin xyz="0.200041 -0.15066 -0.35166" rpy="0 0 0" />
            <geometry>
                <mesh filename="file://$(find cika_description)/meshes/right_gripper_1.stl"
                    scale="0.001 0.001 0.001" />
            </geometry>
            <material name="silver" />
        </visual>
        <collision>
            <origin xyz="0.200041 -0.15066 -0.35166" rpy="0 0 0" />
            <geometry>
                <mesh filename="file://$(find cika_description)/meshes/right_gripper_1.stl"
                    scale="0.001 0.001 0.001" />
            </geometry>
        </collision>
    </link>

    <joint name="Revolute 1" type="continuous">
        <origin xyz="-0.100089 0.332003 0.0962" rpy="0 0 0" />
        <parent link="base_link" />
        <child link="left_front_wheel_1" />
        <axis xyz="0.0 1.0 0.0" />
    </joint>

    <joint name="Revolute 2" type="continuous">
        <origin xyz="-0.47736 0.332003 0.0962" rpy="0 0 0" />
        <parent link="base_link" />
        <child link="left_back_wheel_1" />
        <axis xyz="0.0 1.0 0.0" />
    </joint>

    <joint name="Revolute 3" type="continuous">
        <origin xyz="-0.099911 -0.031017 0.0962" rpy="0 0 0" />
        <parent link="base_link" />
        <child link="right_front_wheel_1" />
        <axis xyz="-0.0 1.0 0.0" />
    </joint>

    <joint name="Revolute 4" type="continuous">
        <origin xyz="-0.47736 -0.030997 0.0962" rpy="0 0 0" />
        <parent link="base_link" />
        <child link="right_back_wheel_1" />
        <axis xyz="0.0 1.0 0.0" />
    </joint>

    <joint name="Rigid 5" type="fixed">
        <origin xyz="-0.038004 0.265503 0.193866" rpy="0 0 0" />
        <parent link="base_link" />
        <child link="lidar_1" />
    </joint>

    <joint name="Rigid 7" type="fixed">
        <origin xyz="-0.517714 0.150503 0.657116" rpy="0 0 0" />
        <parent link="base_link" />
        <child link="OAKDcamera_1" />
    </joint>

    <joint name="Rigid 8" type="fixed">
        <origin xyz="-0.069976 0.15041 0.149616" rpy="0 0 0" />
        <parent link="base_link" />
        <child link="arm_bottom_1" />
    </joint>

    <joint name="Revolute 9" type="continuous">
        <origin xyz="-0.055 0.0 0.079555" rpy="0 0 0" />
        <parent link="arm_bottom_1" />
        <child link="turntable_1" />
        <axis xyz="0.0 -0.0 1.0" />
    </joint>

    <joint name="Revolute 10" type="revolute">
        <origin xyz="0.00025 -0.0318 0.0655" rpy="0 0 0" />
        <parent link="turntable_1" />
        <child link="lower_arm_1" />
        <axis xyz="-0.0 1.0 0.0" />
        <limit upper="3.420845" lower="0.0" effort="100" velocity="100" />
    </joint>

    <joint name="Revolute 11" type="revolute">
        <origin xyz="-0.183288 0.0555 -0.025108" rpy="0 0 0" />
        <parent link="lower_arm_1" />
        <child link="center_arm_1" />
        <axis xyz="0.0 -1.0 -0.0" />
        <limit upper="2.617994" lower="-0.349066" effort="100" velocity="100" />
    </joint>

    <joint name="Revolute 12" type="revolute">
        <origin xyz="-0.045533 0.0065 0.108319" rpy="0 0 0" />
        <parent link="center_arm_1" />
        <child link="upper_arm_1" />
        <axis xyz="-0.0 1.0 0.0" />
        <limit upper="0.349066" lower="-2.094395" effort="100" velocity="100" />
    </joint>

    <joint name="Revolute 13" type="revolute">
        <origin xyz="0.081028 -0.02995 -0.004201" rpy="0 0 0" />
        <parent link="upper_arm_1" />
        <child link="gripper_mount_1" />
        <axis xyz="0.956814 -0.0 -0.290702" />
        <limit upper="0.785398" lower="-0.785398" effort="100" velocity="100" />
    </joint>

    <joint name="Revolute 14" type="revolute">
        <origin xyz="0.072478 0.0 -0.022021" rpy="0 0 0" />
        <parent link="gripper_mount_1" />
        <child link="left_gripper_1" />
        <axis xyz="-0.290702 0.0 -0.956814" />
        <limit upper="0.0" lower="-0.785398" effort="100" velocity="100" />
    </joint>

    <joint name="Revolute 15" type="revolute">
        <origin xyz="0.072478 0.0 -0.022021" rpy="0 0 0" />
        <parent link="gripper_mount_1" />
        <child link="right_gripper_1" />
        <axis xyz="-0.290702 0.0 -0.956814" />
        <limit upper="0.785398" lower="0.0" effort="100" velocity="100" />
    </joint>

</robot>